Workbook

Sheet Sheet1
A1: AB | B1: Ram | C1: Chennai | D1: =VLOOKUP(C1,'Sheet2'!A:B,2,false) -> Tamil Nadu
A2: ABU | B2: Abhay | C2: M'luru | D2: =VLOOKUP(C2,'Sheet2'!A:B,2,false) -> Karnataka
A3: ABS | B3: Aravind | C3: Chennai | D3: =VLOOKUP(C3,'Sheet2'!A:B,2,false) -> Tamil Nadu
A4: ACC | B4: Charles | C4: Aduvassery | D4: =VLOOKUP(C4,'Sheet2'!A:B,2,false) -> Kerala
A5: ACT | B5: Ishwaran | C5: NA | D5: =VLOOKUP(C5,'Sheet2'!A:B,2,false) -> NA
A6: ADV | B6: Jacob | C6: Cochin | D6: =VLOOKUP(C6,'Sheet2'!A:B,2,false) -> Tamil Nadu
A7: AE | B7: Vatsa | C7: B’luru | D7: =VLOOKUP(C7,'Sheet2'!A:B,2,false) -> Karnataka
A8: AGJ | B8: Anand | C8: Ahm’bad | D8: =VLOOKUP(C8,'Sheet2'!A:B,2,false) -> Gujarat
A9: AIR | B9: Viji | C9: Chennai | D9: =VLOOKUP(C9,'Sheet2'!A:B,2,false) -> Tamil Nadu
A10: AIT | B10: Purushu Wayanad | C10: NA | D10: =VLOOKUP(C10,'Sheet2'!A:B,2,false) -> NA
A11: AJF | B11: Ajay | C11: Adur | D11: =VLOOKUP(C11,'Sheet2'!A:B,2,false) -> Karnataka
A12: AJL | B12: Alex | C12: Kottayam | D12: =VLOOKUP(C12,'Sheet2'!A:B,2,false) -> Kerala
... A46: AYN | B46: Jahnavi | C46: Hyd | D46: =VLOOKUP(C46,'Sheet2'!A:B,2,false) -> Telangana
A47: AZK | B47: Kishore | C47: Hyd | D47: =VLOOKUP(C47,'Sheet2'!A:B,2,false) -> Telangana | E47: (Old 3ONG)
A48: AZR | B48: Ashraf | C48: NA | D48: =VLOOKUP(C48,'Sheet2'!A:B,2,false) -> NA
A49: AZS | B49: Atul | C49: Kolhapur | D49: =VLOOKUP(C49,'Sheet2'!A:B,2,false) -> Maharashtra | E49: (FT 710)
A50: BBA | B50: Babu | C50: Cochin | D50: =VLOOKUP(C50,'Sheet2'!A:B,2,false) -> Tamil Nadu
A51: BBF | B51: Arunkumar | C51: Chennai | D51: =VLOOKUP(C51,'Sheet2'!A:B,2,false) -> Tamil Nadu
A52: BBU | B52: Balu | C52: Visakhapatnam | D52: =VLOOKUP(C52,'Sheet2'!A:B,2,false) -> Andhra Pradesh
A53: 3BBW | B53: Prasad | C53: Ker | D53: =VLOOKUP(C53,'Sheet2'!A:B,2,false) -> Kerala
A54: 3BCG | B54: Prabhu | C54: M'lore | D54: =VLOOKUP(C54,'Sheet2'!A:B,2,false) -> Karnataka
A55: 3BCM | B55: Senthil | C55: Namakkal | D55: =VLOOKUP(C55,'Sheet2'!A:B,2,false) -> Tamil Nadu
A56: 3BEO | B56: Jitu | C56: NA | D56: =VLOOKUP(C56,'Sheet2'!A:B,2,false) -> NA
A57: BFO | B57: Challappan | C57: Tirupur | D57: =VLOOKUP(C57,'Sheet2'!A:B,2,false) -> Tamil Nadu
A58: BGC | B58: JP | C58: Ker | D58: =VLOOKUP(C58,'Sheet2'!A:B,2,false) -> Kerala
A59: BGG | B59: Hegde | C59: Belgaum | D59: =VLOOKUP(C59,'Sheet2'!A:B,2,false) -> Karnataka
A60: 3BGK | B60: Neel | C60: Tiruchirappalli | D60: =VLOOKUP(C60,'Sheet2'!A:B,2,false) -> Tamil Nadu
A61: 3BGS | B61: Dr. Prabhu | C61: Mlore | D61: =VLOOKUP(C61,'Sheet2'!A:B,2,false) -> Karnataka
... A68: BOA | B68: Sam | C68: Chennai | D68: =VLOOKUP(C68,'Sheet2'!A:B,2,false) -> Tamil Nadu
A69: 3BOA | B69: Aryan | C69: B’luru | D69: =VLOOKUP(C69,'Sheet2'!A:B,2,false) -> Karnataka | E69: (s/o 2RMS)
A70: 3BOD | B70: Nagesh Joshi | C70: Sirsi | D70: =VLOOKUP(C70,'Sheet2'!A:B,2,false) -> Karnataka
A71: 3BOJ | B71: Bejoy | C71: B’luru | D71: =VLOOKUP(C71,'Sheet2'!A:B,2,false) -> Karnataka
A72: 3BOP | B72: Bopanna | C72: B’luru | D72: =VLOOKUP(C72,'Sheet2'!A:B,2,false) -> Karnataka
A73: BOS | B73: Rajendra | C73: Varkala | D73: =VLOOKUP(C73,'Sheet2'!A:B,2,false) -> Kerala
A74: 3BPQ | B74: Arun | C74: Hyd | D74: =VLOOKUP(C74,'Sheet2'!A:B,2,false) -> Telangana
A75: 3BQD | B75: Ashraf | C75: Mavoor, Calicut | D75: =VLOOKUP(C75,'Sheet2'!A:B,2,false) -> Kerala
A76: 3BQE | B76: George | C76: Calicut | D76: =VLOOKUP(C76,'Sheet2'!A:B,2,false) -> Kerala
A77: BQN | B77: Dr. Manu | C77: NA | D77: =VLOOKUP(C77,'Sheet2'!A:B,2,false) -> NA
A78: 3BQT | B78: Narayan | C78: Palakkad | D78: =VLOOKUP(C78,'Sheet2'!A:B,2,false) -> Kerala
A79: BR | B79: Basheer | C79: Penanani | D79: =VLOOKUP(C79,'Sheet2'!A:B,2,false) -> Tamil Nadu
...

Sheet Sheet2
A1: Chennai | B1: Tamil Nadu
A2: Mluru | B2: Karnataka
A3: Aduvassery | B3: Kerala
A4: Kochi | B4: Kerala
A5: Bluru | B5: Karnataka
A6: Ahmbad | B6: Gujarat
A7: Adur | B7: Karnataka
A8: Kottayam | B8: Kerala
A9: Namakkal | B9: Tamil Nadu
A10: Worli Mumbai | B10: Maharashtra
A11: Pondicheri | B11: Tamil Nadu
A12: Mumbai | B12: Maharashtra
... A335: Thodupuza Ker | B335: Kerala
